
<mujoco model="the_beginning">
<visual>
<headlight ambient="0.5 0.5 0.5"/>
</visual>
<option timestep="0.01" density="1000" viscosity="1.002e-3"/>



<worldbody>
<light diffuse=".5 .5 .5" pos="0 0 3" dir="0 0 -1"/>
<geom type="plane" size="20 20 0.1" rgba="0 .8 .2 1"/>

<body pos="0 0 30"  euler="0 0 0">
<joint type="free" axis="-1 0 0" pos="0 0 -0.5"/>
<geom type="box" size="1.58" fromto="0 0 0 0 0 1" rgba="225 0 225 1" mass="1"/>


    <body pos="-0.7457344250318846 -0.08247455923980451 0" euler="180 0 0">
        <joint name="1_elbow" type="hinge" axis="-1 0 0" pos="0 0 0" range="-50 50"/>
        <geom type="ellipsoid" size="0.1" fromto="0 0 0 0 0 1" rgba="0 0 1 1"/>
    
        <body pos="0 0 1" euler="67 17 86">
            <joint name="1_elbow1" type="hinge" axis="-1 0 0" pos="0 0 0" range="-50 50"/>
            <geom type="ellipsoid" size="0.1" fromto="0 0 0 0 0 1" rgba="0 0 1 1"/>
        
        <body pos="0 0 1" euler="49 109 31">
            <joint name="1_elbow2" type="hinge" axis="-1 0 0" pos="0 0 0" range="-50 50"/>
            <geom type="ellipsoid" size="0.1" fromto="0 0 0 0 0 1" rgba="0 0 1 1"/>
        
        <body pos="0 0 1" euler="27 56 23">
            <joint name="1_elbow3" type="hinge" axis="-1 0 0" pos="0 0 0" range="-50 50"/>
            <geom type="ellipsoid" size="0.1" fromto="0 0 0 0 0 1" rgba="0 0 1 1"/>
        
        <body pos="0 0 1" euler="44 40 9">
            <joint name="1_elbow4" type="hinge" axis="-1 0 0" pos="0 0 0" range="-50 50"/>
            <geom type="ellipsoid" size="0.1" fromto="0 0 0 0 0 1" rgba="0 0 1 1"/>
        
        <body pos="0 0 1" euler="92 12 75">
            <joint name="1_elbow5" type="hinge" axis="-1 0 0" pos="0 0 0" range="-50 50"/>
            <geom type="ellipsoid" size="0.1" fromto="0 0 0 0 0 1" rgba="0 0 1 1"/>
        
        <body pos="0 0 1" euler="7 35 16">
            <joint name="1_elbow6" type="hinge" axis="-1 0 0" pos="0 0 0" range="-50 50"/>
            <geom type="ellipsoid" size="0.1" fromto="0 0 0 0 0 1" rgba="0 0 1 1"/>
        
        <body pos="0 0 1" euler="31 34 34">
            <joint name="1_elbow7" type="hinge" axis="-1 0 0" pos="0 0 0" range="-50 50"/>
            <geom type="ellipsoid" size="0.1" fromto="0 0 0 0 0 1" rgba="0 0 1 1"/>
        
        <body pos="0 0 1" euler="40 72 91">
            <joint name="1_elbow8" type="hinge" axis="-1 0 0" pos="0 0 0" range="-50 50"/>
            <geom type="ellipsoid" size="0.1" fromto="0 0 0 0 0 1" rgba="0 0 1 1"/>
        
        <body pos="0 0 1" euler="36 62 29">
            <joint name="1_elbow9" type="hinge" axis="-1 0 0" pos="0 0 0" range="-50 50"/>
            <geom type="ellipsoid" size="0.1" fromto="0 0 0 0 0 1" rgba="0 0 1 1"/>
        
        </body>

        
        </body>

        
        </body>

        
        </body>

        
        </body>

        
        </body>

        
        </body>

        
        </body>

        
        </body>

        
        </body>

        

    <body pos="-0.23402789037711735 -0.295696606180677 0" euler="180 0 0">
        <joint name="2_elbow" type="hinge" axis="-1 0 0" pos="0 0 0" range="-50 50"/>
        <geom type="ellipsoid" size="0.1" fromto="0 0 0 0 0 1" rgba="0 0 1 1"/>
    
        <body pos="0 0 1" euler="92 82 106">
            <joint name="2_elbow1" type="hinge" axis="-1 0 0" pos="0 0 0" range="-50 50"/>
            <geom type="ellipsoid" size="0.1" fromto="0 0 0 0 0 1" rgba="0 0 1 1"/>
        
        <body pos="0 0 1" euler="108 94 51">
            <joint name="2_elbow2" type="hinge" axis="-1 0 0" pos="0 0 0" range="-50 50"/>
            <geom type="ellipsoid" size="0.1" fromto="0 0 0 0 0 1" rgba="0 0 1 1"/>
        
        <body pos="0 0 1" euler="111 116 25">
            <joint name="2_elbow3" type="hinge" axis="-1 0 0" pos="0 0 0" range="-50 50"/>
            <geom type="ellipsoid" size="0.1" fromto="0 0 0 0 0 1" rgba="0 0 1 1"/>
        
        <body pos="0 0 1" euler="5 51 71">
            <joint name="2_elbow4" type="hinge" axis="-1 0 0" pos="0 0 0" range="-50 50"/>
            <geom type="ellipsoid" size="0.1" fromto="0 0 0 0 0 1" rgba="0 0 1 1"/>
        
        <body pos="0 0 1" euler="20 113 12">
            <joint name="2_elbow5" type="hinge" axis="-1 0 0" pos="0 0 0" range="-50 50"/>
            <geom type="ellipsoid" size="0.1" fromto="0 0 0 0 0 1" rgba="0 0 1 1"/>
        
        <body pos="0 0 1" euler="70 98 36">
            <joint name="2_elbow6" type="hinge" axis="-1 0 0" pos="0 0 0" range="-50 50"/>
            <geom type="ellipsoid" size="0.1" fromto="0 0 0 0 0 1" rgba="0 0 1 1"/>
        
        <body pos="0 0 1" euler="16 61 24">
            <joint name="2_elbow7" type="hinge" axis="-1 0 0" pos="0 0 0" range="-50 50"/>
            <geom type="ellipsoid" size="0.1" fromto="0 0 0 0 0 1" rgba="0 0 1 1"/>
        
        <body pos="0 0 1" euler="60 59 17">
            <joint name="2_elbow8" type="hinge" axis="-1 0 0" pos="0 0 0" range="-50 50"/>
            <geom type="ellipsoid" size="0.1" fromto="0 0 0 0 0 1" rgba="0 0 1 1"/>
        
        <body pos="0 0 1" euler="34 76 90">
            <joint name="2_elbow9" type="hinge" axis="-1 0 0" pos="0 0 0" range="-50 50"/>
            <geom type="ellipsoid" size="0.1" fromto="0 0 0 0 0 1" rgba="0 0 1 1"/>
        
        </body>

        
        </body>

        
        </body>

        
        </body>

        
        </body>

        
        </body>

        
        </body>

        
        </body>

        
        </body>

        
        </body>

        

    <body pos="0.3314879553337018 0.6503717768372748 0" euler="180 0 0">
        <joint name="3_elbow" type="hinge" axis="-1 0 0" pos="0 0 0" range="-50 50"/>
        <geom type="ellipsoid" size="0.1" fromto="0 0 0 0 0 1" rgba="0 0 1 1"/>
    
        <body pos="0 0 1" euler="47 8 84">
            <joint name="3_elbow1" type="hinge" axis="-1 0 0" pos="0 0 0" range="-50 50"/>
            <geom type="ellipsoid" size="0.1" fromto="0 0 0 0 0 1" rgba="0 0 1 1"/>
        
        <body pos="0 0 1" euler="50 117 64">
            <joint name="3_elbow2" type="hinge" axis="-1 0 0" pos="0 0 0" range="-50 50"/>
            <geom type="ellipsoid" size="0.1" fromto="0 0 0 0 0 1" rgba="0 0 1 1"/>
        
        <body pos="0 0 1" euler="31 51 98">
            <joint name="3_elbow3" type="hinge" axis="-1 0 0" pos="0 0 0" range="-50 50"/>
            <geom type="ellipsoid" size="0.1" fromto="0 0 0 0 0 1" rgba="0 0 1 1"/>
        
        <body pos="0 0 1" euler="35 41 8">
            <joint name="3_elbow4" type="hinge" axis="-1 0 0" pos="0 0 0" range="-50 50"/>
            <geom type="ellipsoid" size="0.1" fromto="0 0 0 0 0 1" rgba="0 0 1 1"/>
        
        <body pos="0 0 1" euler="30 89 77">
            <joint name="3_elbow5" type="hinge" axis="-1 0 0" pos="0 0 0" range="-50 50"/>
            <geom type="ellipsoid" size="0.1" fromto="0 0 0 0 0 1" rgba="0 0 1 1"/>
        
        <body pos="0 0 1" euler="29 120 88">
            <joint name="3_elbow6" type="hinge" axis="-1 0 0" pos="0 0 0" range="-50 50"/>
            <geom type="ellipsoid" size="0.1" fromto="0 0 0 0 0 1" rgba="0 0 1 1"/>
        
        <body pos="0 0 1" euler="91 18 91">
            <joint name="3_elbow7" type="hinge" axis="-1 0 0" pos="0 0 0" range="-50 50"/>
            <geom type="ellipsoid" size="0.1" fromto="0 0 0 0 0 1" rgba="0 0 1 1"/>
        
        <body pos="0 0 1" euler="109 33 12">
            <joint name="3_elbow8" type="hinge" axis="-1 0 0" pos="0 0 0" range="-50 50"/>
            <geom type="ellipsoid" size="0.1" fromto="0 0 0 0 0 1" rgba="0 0 1 1"/>
        
        <body pos="0 0 1" euler="48 115 111">
            <joint name="3_elbow9" type="hinge" axis="-1 0 0" pos="0 0 0" range="-50 50"/>
            <geom type="ellipsoid" size="0.1" fromto="0 0 0 0 0 1" rgba="0 0 1 1"/>
        
        </body>

        
        </body>

        
        </body>

        
        </body>

        
        </body>

        
        </body>

        
        </body>

        
        </body>

        
        </body>

        
        </body>

        

    <body pos="-0.4562254149455524 0.5054844651929615 0" euler="180 0 0">
        <joint name="4_elbow" type="hinge" axis="-1 0 0" pos="0 0 0" range="-50 50"/>
        <geom type="ellipsoid" size="0.1" fromto="0 0 0 0 0 1" rgba="0 0 1 1"/>
    
        <body pos="0 0 1" euler="30 96 59">
            <joint name="4_elbow1" type="hinge" axis="-1 0 0" pos="0 0 0" range="-50 50"/>
            <geom type="ellipsoid" size="0.1" fromto="0 0 0 0 0 1" rgba="0 0 1 1"/>
        
        <body pos="0 0 1" euler="18 25 58">
            <joint name="4_elbow2" type="hinge" axis="-1 0 0" pos="0 0 0" range="-50 50"/>
            <geom type="ellipsoid" size="0.1" fromto="0 0 0 0 0 1" rgba="0 0 1 1"/>
        
        <body pos="0 0 1" euler="57 12 108">
            <joint name="4_elbow3" type="hinge" axis="-1 0 0" pos="0 0 0" range="-50 50"/>
            <geom type="ellipsoid" size="0.1" fromto="0 0 0 0 0 1" rgba="0 0 1 1"/>
        
        <body pos="0 0 1" euler="113 28 85">
            <joint name="4_elbow4" type="hinge" axis="-1 0 0" pos="0 0 0" range="-50 50"/>
            <geom type="ellipsoid" size="0.1" fromto="0 0 0 0 0 1" rgba="0 0 1 1"/>
        
        <body pos="0 0 1" euler="16 98 4">
            <joint name="4_elbow5" type="hinge" axis="-1 0 0" pos="0 0 0" range="-50 50"/>
            <geom type="ellipsoid" size="0.1" fromto="0 0 0 0 0 1" rgba="0 0 1 1"/>
        
        <body pos="0 0 1" euler="109 100 5">
            <joint name="4_elbow6" type="hinge" axis="-1 0 0" pos="0 0 0" range="-50 50"/>
            <geom type="ellipsoid" size="0.1" fromto="0 0 0 0 0 1" rgba="0 0 1 1"/>
        
        <body pos="0 0 1" euler="51 17 13">
            <joint name="4_elbow7" type="hinge" axis="-1 0 0" pos="0 0 0" range="-50 50"/>
            <geom type="ellipsoid" size="0.1" fromto="0 0 0 0 0 1" rgba="0 0 1 1"/>
        
        <body pos="0 0 1" euler="78 76 96">
            <joint name="4_elbow8" type="hinge" axis="-1 0 0" pos="0 0 0" range="-50 50"/>
            <geom type="ellipsoid" size="0.1" fromto="0 0 0 0 0 1" rgba="0 0 1 1"/>
        
        <body pos="0 0 1" euler="17 55 1">
            <joint name="4_elbow9" type="hinge" axis="-1 0 0" pos="0 0 0" range="-50 50"/>
            <geom type="ellipsoid" size="0.1" fromto="0 0 0 0 0 1" rgba="0 0 1 1"/>
        
        </body>

        
        </body>

        
        </body>

        
        </body>

        
        </body>

        
        </body>

        
        </body>

        
        </body>

        
        </body>

        
        </body>

        

    <body pos="0.38448746985295634 -0.4299388288982894 0" euler="180 0 0">
        <joint name="5_elbow" type="hinge" axis="-1 0 0" pos="0 0 0" range="-50 50"/>
        <geom type="ellipsoid" size="0.1" fromto="0 0 0 0 0 1" rgba="0 0 1 1"/>
    
        <body pos="0 0 1" euler="16 5 60">
            <joint name="5_elbow1" type="hinge" axis="-1 0 0" pos="0 0 0" range="-50 50"/>
            <geom type="ellipsoid" size="0.1" fromto="0 0 0 0 0 1" rgba="0 0 1 1"/>
        
        <body pos="0 0 1" euler="60 106 74">
            <joint name="5_elbow2" type="hinge" axis="-1 0 0" pos="0 0 0" range="-50 50"/>
            <geom type="ellipsoid" size="0.1" fromto="0 0 0 0 0 1" rgba="0 0 1 1"/>
        
        <body pos="0 0 1" euler="25 73 79">
            <joint name="5_elbow3" type="hinge" axis="-1 0 0" pos="0 0 0" range="-50 50"/>
            <geom type="ellipsoid" size="0.1" fromto="0 0 0 0 0 1" rgba="0 0 1 1"/>
        
        <body pos="0 0 1" euler="80 7 97">
            <joint name="5_elbow4" type="hinge" axis="-1 0 0" pos="0 0 0" range="-50 50"/>
            <geom type="ellipsoid" size="0.1" fromto="0 0 0 0 0 1" rgba="0 0 1 1"/>
        
        <body pos="0 0 1" euler="92 73 7">
            <joint name="5_elbow5" type="hinge" axis="-1 0 0" pos="0 0 0" range="-50 50"/>
            <geom type="ellipsoid" size="0.1" fromto="0 0 0 0 0 1" rgba="0 0 1 1"/>
        
        <body pos="0 0 1" euler="41 83 56">
            <joint name="5_elbow6" type="hinge" axis="-1 0 0" pos="0 0 0" range="-50 50"/>
            <geom type="ellipsoid" size="0.1" fromto="0 0 0 0 0 1" rgba="0 0 1 1"/>
        
        <body pos="0 0 1" euler="87 103 44">
            <joint name="5_elbow7" type="hinge" axis="-1 0 0" pos="0 0 0" range="-50 50"/>
            <geom type="ellipsoid" size="0.1" fromto="0 0 0 0 0 1" rgba="0 0 1 1"/>
        
        <body pos="0 0 1" euler="119 98 75">
            <joint name="5_elbow8" type="hinge" axis="-1 0 0" pos="0 0 0" range="-50 50"/>
            <geom type="ellipsoid" size="0.1" fromto="0 0 0 0 0 1" rgba="0 0 1 1"/>
        
        <body pos="0 0 1" euler="113 52 42">
            <joint name="5_elbow9" type="hinge" axis="-1 0 0" pos="0 0 0" range="-50 50"/>
            <geom type="ellipsoid" size="0.1" fromto="0 0 0 0 0 1" rgba="0 0 1 1"/>
        
        </body>

        
        </body>

        
        </body>

        
        </body>

        
        </body>

        
        </body>

        
        </body>

        
        </body>

        
        </body>

        
        </body>

        

    <body pos="-0.4765344430470234 -0.179082771382149 0" euler="180 0 0">
        <joint name="6_elbow" type="hinge" axis="-1 0 0" pos="0 0 0" range="-50 50"/>
        <geom type="ellipsoid" size="0.1" fromto="0 0 0 0 0 1" rgba="0 0 1 1"/>
    
        <body pos="0 0 1" euler="98 85 37">
            <joint name="6_elbow1" type="hinge" axis="-1 0 0" pos="0 0 0" range="-50 50"/>
            <geom type="ellipsoid" size="0.1" fromto="0 0 0 0 0 1" rgba="0 0 1 1"/>
        
        <body pos="0 0 1" euler="80 102 90">
            <joint name="6_elbow2" type="hinge" axis="-1 0 0" pos="0 0 0" range="-50 50"/>
            <geom type="ellipsoid" size="0.1" fromto="0 0 0 0 0 1" rgba="0 0 1 1"/>
        
        <body pos="0 0 1" euler="97 79 110">
            <joint name="6_elbow3" type="hinge" axis="-1 0 0" pos="0 0 0" range="-50 50"/>
            <geom type="ellipsoid" size="0.1" fromto="0 0 0 0 0 1" rgba="0 0 1 1"/>
        
        <body pos="0 0 1" euler="53 52 30">
            <joint name="6_elbow4" type="hinge" axis="-1 0 0" pos="0 0 0" range="-50 50"/>
            <geom type="ellipsoid" size="0.1" fromto="0 0 0 0 0 1" rgba="0 0 1 1"/>
        
        <body pos="0 0 1" euler="20 24 63">
            <joint name="6_elbow5" type="hinge" axis="-1 0 0" pos="0 0 0" range="-50 50"/>
            <geom type="ellipsoid" size="0.1" fromto="0 0 0 0 0 1" rgba="0 0 1 1"/>
        
        <body pos="0 0 1" euler="59 88 19">
            <joint name="6_elbow6" type="hinge" axis="-1 0 0" pos="0 0 0" range="-50 50"/>
            <geom type="ellipsoid" size="0.1" fromto="0 0 0 0 0 1" rgba="0 0 1 1"/>
        
        <body pos="0 0 1" euler="46 87 118">
            <joint name="6_elbow7" type="hinge" axis="-1 0 0" pos="0 0 0" range="-50 50"/>
            <geom type="ellipsoid" size="0.1" fromto="0 0 0 0 0 1" rgba="0 0 1 1"/>
        
        <body pos="0 0 1" euler="65 78 98">
            <joint name="6_elbow8" type="hinge" axis="-1 0 0" pos="0 0 0" range="-50 50"/>
            <geom type="ellipsoid" size="0.1" fromto="0 0 0 0 0 1" rgba="0 0 1 1"/>
        
        <body pos="0 0 1" euler="35 38 38">
            <joint name="6_elbow9" type="hinge" axis="-1 0 0" pos="0 0 0" range="-50 50"/>
            <geom type="ellipsoid" size="0.1" fromto="0 0 0 0 0 1" rgba="0 0 1 1"/>
        
        </body>

        
        </body>

        
        </body>

        
        </body>

        
        </body>

        
        </body>

        
        </body>

        
        </body>

        
        </body>

        
        </body>

        

    <body pos="-0.47100925381279635 0.46963333027612775 0" euler="180 0 0">
        <joint name="7_elbow" type="hinge" axis="-1 0 0" pos="0 0 0" range="-50 50"/>
        <geom type="ellipsoid" size="0.1" fromto="0 0 0 0 0 1" rgba="0 0 1 1"/>
    
        <body pos="0 0 1" euler="13 101 75">
            <joint name="7_elbow1" type="hinge" axis="-1 0 0" pos="0 0 0" range="-50 50"/>
            <geom type="ellipsoid" size="0.1" fromto="0 0 0 0 0 1" rgba="0 0 1 1"/>
        
        <body pos="0 0 1" euler="85 31 111">
            <joint name="7_elbow2" type="hinge" axis="-1 0 0" pos="0 0 0" range="-50 50"/>
            <geom type="ellipsoid" size="0.1" fromto="0 0 0 0 0 1" rgba="0 0 1 1"/>
        
        <body pos="0 0 1" euler="99 10 31">
            <joint name="7_elbow3" type="hinge" axis="-1 0 0" pos="0 0 0" range="-50 50"/>
            <geom type="ellipsoid" size="0.1" fromto="0 0 0 0 0 1" rgba="0 0 1 1"/>
        
        <body pos="0 0 1" euler="115 0 31">
            <joint name="7_elbow4" type="hinge" axis="-1 0 0" pos="0 0 0" range="-50 50"/>
            <geom type="ellipsoid" size="0.1" fromto="0 0 0 0 0 1" rgba="0 0 1 1"/>
        
        <body pos="0 0 1" euler="9 58 13">
            <joint name="7_elbow5" type="hinge" axis="-1 0 0" pos="0 0 0" range="-50 50"/>
            <geom type="ellipsoid" size="0.1" fromto="0 0 0 0 0 1" rgba="0 0 1 1"/>
        
        <body pos="0 0 1" euler="6 111 79">
            <joint name="7_elbow6" type="hinge" axis="-1 0 0" pos="0 0 0" range="-50 50"/>
            <geom type="ellipsoid" size="0.1" fromto="0 0 0 0 0 1" rgba="0 0 1 1"/>
        
        <body pos="0 0 1" euler="99 60 25">
            <joint name="7_elbow7" type="hinge" axis="-1 0 0" pos="0 0 0" range="-50 50"/>
            <geom type="ellipsoid" size="0.1" fromto="0 0 0 0 0 1" rgba="0 0 1 1"/>
        
        <body pos="0 0 1" euler="1 66 65">
            <joint name="7_elbow8" type="hinge" axis="-1 0 0" pos="0 0 0" range="-50 50"/>
            <geom type="ellipsoid" size="0.1" fromto="0 0 0 0 0 1" rgba="0 0 1 1"/>
        
        <body pos="0 0 1" euler="81 63 74">
            <joint name="7_elbow9" type="hinge" axis="-1 0 0" pos="0 0 0" range="-50 50"/>
            <geom type="ellipsoid" size="0.1" fromto="0 0 0 0 0 1" rgba="0 0 1 1"/>
        
        </body>

        
        </body>

        
        </body>

        
        </body>

        
        </body>

        
        </body>

        
        </body>

        
        </body>

        
        </body>

        
        </body>

        

    <body pos="0.23060947050058145 -0.7750584383928638 0" euler="180 0 0">
        <joint name="8_elbow" type="hinge" axis="-1 0 0" pos="0 0 0" range="-50 50"/>
        <geom type="ellipsoid" size="0.1" fromto="0 0 0 0 0 1" rgba="0 0 1 1"/>
    
        <body pos="0 0 1" euler="1 48 5">
            <joint name="8_elbow1" type="hinge" axis="-1 0 0" pos="0 0 0" range="-50 50"/>
            <geom type="ellipsoid" size="0.1" fromto="0 0 0 0 0 1" rgba="0 0 1 1"/>
        
        <body pos="0 0 1" euler="113 2 75">
            <joint name="8_elbow2" type="hinge" axis="-1 0 0" pos="0 0 0" range="-50 50"/>
            <geom type="ellipsoid" size="0.1" fromto="0 0 0 0 0 1" rgba="0 0 1 1"/>
        
        <body pos="0 0 1" euler="85 91 72">
            <joint name="8_elbow3" type="hinge" axis="-1 0 0" pos="0 0 0" range="-50 50"/>
            <geom type="ellipsoid" size="0.1" fromto="0 0 0 0 0 1" rgba="0 0 1 1"/>
        
        <body pos="0 0 1" euler="19 87 80">
            <joint name="8_elbow4" type="hinge" axis="-1 0 0" pos="0 0 0" range="-50 50"/>
            <geom type="ellipsoid" size="0.1" fromto="0 0 0 0 0 1" rgba="0 0 1 1"/>
        
        <body pos="0 0 1" euler="28 107 103">
            <joint name="8_elbow5" type="hinge" axis="-1 0 0" pos="0 0 0" range="-50 50"/>
            <geom type="ellipsoid" size="0.1" fromto="0 0 0 0 0 1" rgba="0 0 1 1"/>
        
        <body pos="0 0 1" euler="68 35 43">
            <joint name="8_elbow6" type="hinge" axis="-1 0 0" pos="0 0 0" range="-50 50"/>
            <geom type="ellipsoid" size="0.1" fromto="0 0 0 0 0 1" rgba="0 0 1 1"/>
        
        <body pos="0 0 1" euler="67 108 104">
            <joint name="8_elbow7" type="hinge" axis="-1 0 0" pos="0 0 0" range="-50 50"/>
            <geom type="ellipsoid" size="0.1" fromto="0 0 0 0 0 1" rgba="0 0 1 1"/>
        
        <body pos="0 0 1" euler="1 86 4">
            <joint name="8_elbow8" type="hinge" axis="-1 0 0" pos="0 0 0" range="-50 50"/>
            <geom type="ellipsoid" size="0.1" fromto="0 0 0 0 0 1" rgba="0 0 1 1"/>
        
        <body pos="0 0 1" euler="72 117 23">
            <joint name="8_elbow9" type="hinge" axis="-1 0 0" pos="0 0 0" range="-50 50"/>
            <geom type="ellipsoid" size="0.1" fromto="0 0 0 0 0 1" rgba="0 0 1 1"/>
        
        </body>

        
        </body>

        
        </body>

        
        </body>

        
        </body>

        
        </body>

        
        </body>

        
        </body>

        
        </body>

        
        </body>

        

    <body pos="0.5408079891310744 -0.5551933055904578 0" euler="180 0 0">
        <joint name="9_elbow" type="hinge" axis="-1 0 0" pos="0 0 0" range="-50 50"/>
        <geom type="ellipsoid" size="0.1" fromto="0 0 0 0 0 1" rgba="0 0 1 1"/>
    
        <body pos="0 0 1" euler="45 22 87">
            <joint name="9_elbow1" type="hinge" axis="-1 0 0" pos="0 0 0" range="-50 50"/>
            <geom type="ellipsoid" size="0.1" fromto="0 0 0 0 0 1" rgba="0 0 1 1"/>
        
        <body pos="0 0 1" euler="65 91 104">
            <joint name="9_elbow2" type="hinge" axis="-1 0 0" pos="0 0 0" range="-50 50"/>
            <geom type="ellipsoid" size="0.1" fromto="0 0 0 0 0 1" rgba="0 0 1 1"/>
        
        <body pos="0 0 1" euler="54 96 58">
            <joint name="9_elbow3" type="hinge" axis="-1 0 0" pos="0 0 0" range="-50 50"/>
            <geom type="ellipsoid" size="0.1" fromto="0 0 0 0 0 1" rgba="0 0 1 1"/>
        
        <body pos="0 0 1" euler="57 113 100">
            <joint name="9_elbow4" type="hinge" axis="-1 0 0" pos="0 0 0" range="-50 50"/>
            <geom type="ellipsoid" size="0.1" fromto="0 0 0 0 0 1" rgba="0 0 1 1"/>
        
        <body pos="0 0 1" euler="40 32 94">
            <joint name="9_elbow5" type="hinge" axis="-1 0 0" pos="0 0 0" range="-50 50"/>
            <geom type="ellipsoid" size="0.1" fromto="0 0 0 0 0 1" rgba="0 0 1 1"/>
        
        <body pos="0 0 1" euler="0 55 80">
            <joint name="9_elbow6" type="hinge" axis="-1 0 0" pos="0 0 0" range="-50 50"/>
            <geom type="ellipsoid" size="0.1" fromto="0 0 0 0 0 1" rgba="0 0 1 1"/>
        
        <body pos="0 0 1" euler="116 96 106">
            <joint name="9_elbow7" type="hinge" axis="-1 0 0" pos="0 0 0" range="-50 50"/>
            <geom type="ellipsoid" size="0.1" fromto="0 0 0 0 0 1" rgba="0 0 1 1"/>
        
        <body pos="0 0 1" euler="17 34 103">
            <joint name="9_elbow8" type="hinge" axis="-1 0 0" pos="0 0 0" range="-50 50"/>
            <geom type="ellipsoid" size="0.1" fromto="0 0 0 0 0 1" rgba="0 0 1 1"/>
        
        <body pos="0 0 1" euler="46 70 111">
            <joint name="9_elbow9" type="hinge" axis="-1 0 0" pos="0 0 0" range="-50 50"/>
            <geom type="ellipsoid" size="0.1" fromto="0 0 0 0 0 1" rgba="0 0 1 1"/>
        
        </body>

        
        </body>

        
        </body>

        
        </body>

        
        </body>

        
        </body>

        
        </body>

        
        </body>

        
        </body>

        
        </body>

        

    <body pos="-0.12828276656565263 0.24442250914968988 0" euler="180 0 0">
        <joint name="10_elbow" type="hinge" axis="-1 0 0" pos="0 0 0" range="-50 50"/>
        <geom type="ellipsoid" size="0.1" fromto="0 0 0 0 0 1" rgba="0 0 1 1"/>
    
        <body pos="0 0 1" euler="46 55 31">
            <joint name="10_elbow1" type="hinge" axis="-1 0 0" pos="0 0 0" range="-50 50"/>
            <geom type="ellipsoid" size="0.1" fromto="0 0 0 0 0 1" rgba="0 0 1 1"/>
        
        <body pos="0 0 1" euler="8 0 80">
            <joint name="10_elbow2" type="hinge" axis="-1 0 0" pos="0 0 0" range="-50 50"/>
            <geom type="ellipsoid" size="0.1" fromto="0 0 0 0 0 1" rgba="0 0 1 1"/>
        
        <body pos="0 0 1" euler="95 76 22">
            <joint name="10_elbow3" type="hinge" axis="-1 0 0" pos="0 0 0" range="-50 50"/>
            <geom type="ellipsoid" size="0.1" fromto="0 0 0 0 0 1" rgba="0 0 1 1"/>
        
        <body pos="0 0 1" euler="30 113 57">
            <joint name="10_elbow4" type="hinge" axis="-1 0 0" pos="0 0 0" range="-50 50"/>
            <geom type="ellipsoid" size="0.1" fromto="0 0 0 0 0 1" rgba="0 0 1 1"/>
        
        <body pos="0 0 1" euler="24 93 26">
            <joint name="10_elbow5" type="hinge" axis="-1 0 0" pos="0 0 0" range="-50 50"/>
            <geom type="ellipsoid" size="0.1" fromto="0 0 0 0 0 1" rgba="0 0 1 1"/>
        
        <body pos="0 0 1" euler="104 108 12">
            <joint name="10_elbow6" type="hinge" axis="-1 0 0" pos="0 0 0" range="-50 50"/>
            <geom type="ellipsoid" size="0.1" fromto="0 0 0 0 0 1" rgba="0 0 1 1"/>
        
        <body pos="0 0 1" euler="34 19 92">
            <joint name="10_elbow7" type="hinge" axis="-1 0 0" pos="0 0 0" range="-50 50"/>
            <geom type="ellipsoid" size="0.1" fromto="0 0 0 0 0 1" rgba="0 0 1 1"/>
        
        <body pos="0 0 1" euler="85 11 40">
            <joint name="10_elbow8" type="hinge" axis="-1 0 0" pos="0 0 0" range="-50 50"/>
            <geom type="ellipsoid" size="0.1" fromto="0 0 0 0 0 1" rgba="0 0 1 1"/>
        
        <body pos="0 0 1" euler="10 15 50">
            <joint name="10_elbow9" type="hinge" axis="-1 0 0" pos="0 0 0" range="-50 50"/>
            <geom type="ellipsoid" size="0.1" fromto="0 0 0 0 0 1" rgba="0 0 1 1"/>
        
        </body>

        
        </body>

        
        </body>

        
        </body>

        
        </body>

        
        </body>

        
        </body>

        
        </body>

        
        </body>

        
        </body>

        
</body>


</worldbody>

<actuator>

    <motor name="1_belly"  gear="40"  joint="1_elbow"/>
    
        <motor name="1_belly_1"  gear="40"  joint="1_elbow1"/>
        
        <motor name="1_belly_2"  gear="40"  joint="1_elbow2"/>
        
        <motor name="1_belly_3"  gear="40"  joint="1_elbow3"/>
        
        <motor name="1_belly_4"  gear="40"  joint="1_elbow4"/>
        
        <motor name="1_belly_5"  gear="40"  joint="1_elbow5"/>
        
        <motor name="1_belly_6"  gear="40"  joint="1_elbow6"/>
        
        <motor name="1_belly_7"  gear="40"  joint="1_elbow7"/>
        
        <motor name="1_belly_8"  gear="40"  joint="1_elbow8"/>
        
        <motor name="1_belly_9"  gear="40"  joint="1_elbow9"/>
        
    <motor name="2_belly"  gear="40"  joint="2_elbow"/>
    
        <motor name="2_belly_1"  gear="40"  joint="2_elbow1"/>
        
        <motor name="2_belly_2"  gear="40"  joint="2_elbow2"/>
        
        <motor name="2_belly_3"  gear="40"  joint="2_elbow3"/>
        
        <motor name="2_belly_4"  gear="40"  joint="2_elbow4"/>
        
        <motor name="2_belly_5"  gear="40"  joint="2_elbow5"/>
        
        <motor name="2_belly_6"  gear="40"  joint="2_elbow6"/>
        
        <motor name="2_belly_7"  gear="40"  joint="2_elbow7"/>
        
        <motor name="2_belly_8"  gear="40"  joint="2_elbow8"/>
        
        <motor name="2_belly_9"  gear="40"  joint="2_elbow9"/>
        
    <motor name="3_belly"  gear="40"  joint="3_elbow"/>
    
        <motor name="3_belly_1"  gear="40"  joint="3_elbow1"/>
        
        <motor name="3_belly_2"  gear="40"  joint="3_elbow2"/>
        
        <motor name="3_belly_3"  gear="40"  joint="3_elbow3"/>
        
        <motor name="3_belly_4"  gear="40"  joint="3_elbow4"/>
        
        <motor name="3_belly_5"  gear="40"  joint="3_elbow5"/>
        
        <motor name="3_belly_6"  gear="40"  joint="3_elbow6"/>
        
        <motor name="3_belly_7"  gear="40"  joint="3_elbow7"/>
        
        <motor name="3_belly_8"  gear="40"  joint="3_elbow8"/>
        
        <motor name="3_belly_9"  gear="40"  joint="3_elbow9"/>
        
    <motor name="4_belly"  gear="40"  joint="4_elbow"/>
    
        <motor name="4_belly_1"  gear="40"  joint="4_elbow1"/>
        
        <motor name="4_belly_2"  gear="40"  joint="4_elbow2"/>
        
        <motor name="4_belly_3"  gear="40"  joint="4_elbow3"/>
        
        <motor name="4_belly_4"  gear="40"  joint="4_elbow4"/>
        
        <motor name="4_belly_5"  gear="40"  joint="4_elbow5"/>
        
        <motor name="4_belly_6"  gear="40"  joint="4_elbow6"/>
        
        <motor name="4_belly_7"  gear="40"  joint="4_elbow7"/>
        
        <motor name="4_belly_8"  gear="40"  joint="4_elbow8"/>
        
        <motor name="4_belly_9"  gear="40"  joint="4_elbow9"/>
        
    <motor name="5_belly"  gear="40"  joint="5_elbow"/>
    
        <motor name="5_belly_1"  gear="40"  joint="5_elbow1"/>
        
        <motor name="5_belly_2"  gear="40"  joint="5_elbow2"/>
        
        <motor name="5_belly_3"  gear="40"  joint="5_elbow3"/>
        
        <motor name="5_belly_4"  gear="40"  joint="5_elbow4"/>
        
        <motor name="5_belly_5"  gear="40"  joint="5_elbow5"/>
        
        <motor name="5_belly_6"  gear="40"  joint="5_elbow6"/>
        
        <motor name="5_belly_7"  gear="40"  joint="5_elbow7"/>
        
        <motor name="5_belly_8"  gear="40"  joint="5_elbow8"/>
        
        <motor name="5_belly_9"  gear="40"  joint="5_elbow9"/>
        
    <motor name="6_belly"  gear="40"  joint="6_elbow"/>
    
        <motor name="6_belly_1"  gear="40"  joint="6_elbow1"/>
        
        <motor name="6_belly_2"  gear="40"  joint="6_elbow2"/>
        
        <motor name="6_belly_3"  gear="40"  joint="6_elbow3"/>
        
        <motor name="6_belly_4"  gear="40"  joint="6_elbow4"/>
        
        <motor name="6_belly_5"  gear="40"  joint="6_elbow5"/>
        
        <motor name="6_belly_6"  gear="40"  joint="6_elbow6"/>
        
        <motor name="6_belly_7"  gear="40"  joint="6_elbow7"/>
        
        <motor name="6_belly_8"  gear="40"  joint="6_elbow8"/>
        
        <motor name="6_belly_9"  gear="40"  joint="6_elbow9"/>
        
    <motor name="7_belly"  gear="40"  joint="7_elbow"/>
    
        <motor name="7_belly_1"  gear="40"  joint="7_elbow1"/>
        
        <motor name="7_belly_2"  gear="40"  joint="7_elbow2"/>
        
        <motor name="7_belly_3"  gear="40"  joint="7_elbow3"/>
        
        <motor name="7_belly_4"  gear="40"  joint="7_elbow4"/>
        
        <motor name="7_belly_5"  gear="40"  joint="7_elbow5"/>
        
        <motor name="7_belly_6"  gear="40"  joint="7_elbow6"/>
        
        <motor name="7_belly_7"  gear="40"  joint="7_elbow7"/>
        
        <motor name="7_belly_8"  gear="40"  joint="7_elbow8"/>
        
        <motor name="7_belly_9"  gear="40"  joint="7_elbow9"/>
        
    <motor name="8_belly"  gear="40"  joint="8_elbow"/>
    
        <motor name="8_belly_1"  gear="40"  joint="8_elbow1"/>
        
        <motor name="8_belly_2"  gear="40"  joint="8_elbow2"/>
        
        <motor name="8_belly_3"  gear="40"  joint="8_elbow3"/>
        
        <motor name="8_belly_4"  gear="40"  joint="8_elbow4"/>
        
        <motor name="8_belly_5"  gear="40"  joint="8_elbow5"/>
        
        <motor name="8_belly_6"  gear="40"  joint="8_elbow6"/>
        
        <motor name="8_belly_7"  gear="40"  joint="8_elbow7"/>
        
        <motor name="8_belly_8"  gear="40"  joint="8_elbow8"/>
        
        <motor name="8_belly_9"  gear="40"  joint="8_elbow9"/>
        
    <motor name="9_belly"  gear="40"  joint="9_elbow"/>
    
        <motor name="9_belly_1"  gear="40"  joint="9_elbow1"/>
        
        <motor name="9_belly_2"  gear="40"  joint="9_elbow2"/>
        
        <motor name="9_belly_3"  gear="40"  joint="9_elbow3"/>
        
        <motor name="9_belly_4"  gear="40"  joint="9_elbow4"/>
        
        <motor name="9_belly_5"  gear="40"  joint="9_elbow5"/>
        
        <motor name="9_belly_6"  gear="40"  joint="9_elbow6"/>
        
        <motor name="9_belly_7"  gear="40"  joint="9_elbow7"/>
        
        <motor name="9_belly_8"  gear="40"  joint="9_elbow8"/>
        
        <motor name="9_belly_9"  gear="40"  joint="9_elbow9"/>
        
    <motor name="10_belly"  gear="40"  joint="10_elbow"/>
    
        <motor name="10_belly_1"  gear="40"  joint="10_elbow1"/>
        
        <motor name="10_belly_2"  gear="40"  joint="10_elbow2"/>
        
        <motor name="10_belly_3"  gear="40"  joint="10_elbow3"/>
        
        <motor name="10_belly_4"  gear="40"  joint="10_elbow4"/>
        
        <motor name="10_belly_5"  gear="40"  joint="10_elbow5"/>
        
        <motor name="10_belly_6"  gear="40"  joint="10_elbow6"/>
        
        <motor name="10_belly_7"  gear="40"  joint="10_elbow7"/>
        
        <motor name="10_belly_8"  gear="40"  joint="10_elbow8"/>
        
        <motor name="10_belly_9"  gear="40"  joint="10_elbow9"/>
        
</actuator>

</mujoco>
