
<mujoco model="snake">



    <visual>
        <headlight ambient="0.5 0.5 0.5"/>
    </visual>


    <option timestep="0.01" gravity="0 0 -1"/>



<!-- Pillars -->

	<worldbody>
		<body pos="3 1 5">
			<joint type="free"/>
			<geom type="box" size=".5 .5 4" rgba="0 .5 .8 1" mass="1000000"/>
		</body>
	</worldbody>

	<worldbody>
		<body pos="1 3 5">
			<joint type="free"/>
			<geom type="box" size=".5 .5 4" rgba="0 .5 .8 1" mass="1000000"/>
		</body>
	</worldbody>

	<worldbody>
		<body pos="-3 1 5">
			<joint type="free"/>
			<geom type="box" size=".5 .5 4" rgba="0 .5 .8 1" mass="1000000"/>
		</body>
	</worldbody>

	<worldbody>
		<body pos="1 -3 5">
			<joint type="free"/>
			<geom type="box" size=".5 .5 4" rgba="0 .5 .8 1" mass="1000000"/>
		</body>
	</worldbody>

	<worldbody>
		<body pos="-1 -2 5">
			<joint type="free"/>
			<geom type="box" size=".5 .5 4" rgba="0 .5 .8 1" mass="1000000"/>
		</body>
	</worldbody>


	<worldbody>
		<body pos="2 -1 5">
			<joint type="free"/>
			<geom type="box" size=".5 .5 4" rgba="0 .5 .8 1" mass="1000000"/>
		</body>
	</worldbody>


	<worldbody>
		<body pos="4 4 5">
			<joint type="free"/>
			<geom type="box" size=".5 .5 3" rgba="0 .5 .8 1" mass="10000"/>
		</body>
	</worldbody>


	<worldbody>
		<body pos="-5 -4 5">
			<joint type="free"/>
			<geom type="box" size=".5 .5 4" rgba="0 .5 .8 1" mass="10000"/>
		</body>
	</worldbody>


	<worldbody>
		<body pos="-4 2 5">
			<joint type="free"/>
			<geom type="box" size=".5 .5 4" rgba="0 .5 .8 1" mass="10000"/>
		</body>
	</worldbody>


	<worldbody>
		<body pos="8 -5 5">
			<joint type="free"/>
			<geom type="box" size=".5 .5 2" rgba="0 .5 .8 1" mass="10000"/>
		</body>
	</worldbody>


	<worldbody>
		<body pos="6 2 5">
			<joint type="free"/>
			<geom type="box" size=".5 .5 3" rgba="0 .5 .8 1" mass="10000"/>
		</body>
	</worldbody>





<!-- Snake -->


    <worldbody>
        <light diffuse=".5 .5 .5" pos="0 0 3" dir="0 0 -1"/>
        <geom type="plane" size="20 20 0.1" rgba="0 .8 .2 1"/>



        <body pos="0 0 1"  euler="0 30 0">
            <joint type="free" axis="-1 0 0" pos="0 0 -0.5"/>
            <geom type="ellipsoid" size=".1" fromto="0 0 0 0 0 1" rgba="225 0 225 1"/>
            
            <body pos="0 0 1" euler="0 0 0">
                <joint name="elbow1" type="hinge" axis="-1 0 0" pos="0 0 0" range="-50 50"/>
                <geom type="ellipsoid" size="0.1" fromto="0 0 0 0 0 1" rgba="225 0 225 1"/>

                <body pos="0 0 1" euler="0 0 0">
                    <joint name="elbow2" type="hinge" axis="-1 0 0" pos="0 0 0" range="-50 50"/>
                    <geom type="ellipsoid" size="0.1" fromto="0 0 0 0 0 1" rgba="225 0 225 1"/>

                    <body pos="0 0 1" euler="0 0 0">
                        <joint name="elbow3" type="hinge" axis="-1 0 0" pos="0 0 0" range="-50 50"/>
                        <geom type="ellipsoid" size="0.1" fromto="0 0 0 0 0 1" rgba="225 0 225 1"/>

                        <body pos="0 0 1" euler="0 0 0">
                            <joint name="elbow4" type="hinge" axis="-1 0 0" pos="0 0 0" range="-50 50"/>
                            <geom type="ellipsoid" size="0.1" fromto="0 0 0 0 0 1" rgba="225 0 225 1"/>

                            <body pos="0 0 1" euler="0 0 0">
                                <joint name="elbow5" type="hinge" axis="-1 0 0" pos="0 0 0" range="-50 50"/>
                                <geom type="ellipsoid" size="0.1" fromto="0 0 0 0 0 1" rgba="225 0 225 1"/> 



                            </body>
                        </body>
                    </body>

                </body>
            </body>
        </body>






    </worldbody>


<!-- Set motors to the hinges -->

    <actuator>
        <motor name="belly_1"  gear="40"  joint="elbow1"/>
        <motor name="belly_2"  gear="40"  joint="elbow2"/>
        <motor name="belly_3"  gear="40"  joint="elbow3"/>
        <motor name="belly_4"  gear="40"  joint="elbow4"/>        
        <motor name="belly_5"  gear="40"  joint="elbow5"/>        
    </actuator>



</mujoco>


















