<mujoco><option>viscosity="0.001002"</option><asset><texture builtin="gradient" height="256" rgb1="0 1 1" rgb2=".2 .3 .4" type="skybox" width="256" /></asset><visual><headlight ambient="0.5 0.5 0.5" /></visual><worldbody><light diffuse=".5 .5 .5" pos="0 0 10" dir="0 0 -1" /><geom name="floor" type="plane" size="50 50 50" rgba="0.9176 0.8078 0.4156 1.0" /><body><freejoint name="body" /><geom name="body" pos="0 0 5" type="box" size="1 1 1" rgba="225 0 225 .5" mass="1" /><body name="leg_0"><geom pos="2 -0.3304722021495867 4.839244297412261" type="box" size="1 0.2 0.05" mass="1" /><joint name="leg_0_Hinge" pos="1.0 -0.16523610107479336 4.789244297412261" axis="0 1 0" range="-10 10" limited="true" /></body><body name="leg_1"><geom pos="-2 0.5071682830477378 4.731481175494474" type="box" size="1 0.2 0.05" mass="1" /><joint name="leg_1_Hinge" pos="-1.0 0.2535841415238689 4.681481175494474" axis="0 -1 0" range="-10 10" limited="true" /></body><body name="leg_2"><geom pos="0.4955702548489218 2 4.567845554843578" type="box" size="0.2 1 0.05" mass="1" /><joint name="leg_2_Hinge" pos="0.2477851274244609 1.0 4.5178455548435785" axis="-1 0 0" range="-10 10" limited="true" /></body><body name="leg_3"><geom pos="2 0.8997178210080685 5.2709506176815255" type="box" size="1 0.2 0.05" mass="1" /><joint name="leg_3_Hinge" pos="1.0 0.44985891050403426 5.220950617681526" axis="0 1 0" range="-10 10" limited="true" /></body><body name="leg_4"><geom pos="-0.43818355674613096 -2 5.420640301714704" type="box" size="0.2 1 0.05" mass="1" /><joint name="leg_4_Hinge" pos="-0.21909177837306548 -1.0 5.370640301714704" axis="1 0 0" range="-10 10" limited="true" /></body><body name="leg_5"><geom pos="-0.27433364997073584 -2 5.496980161949358" type="box" size="0.2 1 0.05" mass="1" /><joint name="leg_5_Hinge" pos="-0.13716682498536792 -1.0 5.446980161949358" axis="1 0 0" range="-10 10" limited="true" /></body><body name="leg_6"><geom pos="-2 0.7191964917076525 5.24130669219395" type="box" size="1 0.2 0.05" mass="1" /><joint name="leg_6_Hinge" pos="-1.0 0.35959824585382627 5.19130669219395" axis="0 -1 0" range="-10 10" limited="true" /></body><body name="leg_7"><geom pos="0.7007600978995012 -2 4.72654103483031" type="box" size="0.2 1 0.05" mass="1" /><joint name="leg_7_Hinge" pos="0.3503800489497506 -1.0 4.6765410348303105" axis="1 0 0" range="-10 10" limited="true" /></body><body name="leg_8"><geom pos="2 0.8184706712971583 4.950821488296894" type="box" size="1 0.2 0.05" mass="1" /><joint name="leg_8_Hinge" pos="1.0 0.40923533564857917 4.900821488296894" axis="0 1 0" range="-10 10" limited="true" /></body><body name="leg_9"><geom pos="4 0.8184706712971583 4.950821488296894" type="box" size="1 0.2 0.05" mass="1" /><joint name="leg_9_Hinge" pos="2.0 0.40923533564857917 4.900821488296894" axis="0 1 0" range="-10 10" limited="true" /></body><body name="leg_10"><geom pos="-0.43818355674613096 -4 5.420640301714704" type="box" size="0.2 1 0.05" mass="1" /><joint name="leg_10_Hinge" pos="-0.21909177837306548 -2.0 5.370640301714704" axis="1 0 0" range="-10 10" limited="true" /></body><body name="leg_11"><geom pos="4 -0.3304722021495867 4.839244297412261" type="box" size="1 0.2 0.05" mass="1" /><joint name="leg_11_Hinge" pos="2.0 -0.16523610107479336 4.789244297412261" axis="0 1 0" range="-10 10" limited="true" /></body><body name="leg_12"><geom pos="0.4955702548489218 4 4.567845554843578" type="box" size="0.2 1 0.05" mass="1" /><joint name="leg_12_Hinge" pos="0.2477851274244609 2.0 4.5178455548435785" axis="-1 0 0" range="-10 10" limited="true" /></body><body name="leg_13"><geom pos="4 0.8997178210080685 5.2709506176815255" type="box" size="1 0.2 0.05" mass="1" /><joint name="leg_13_Hinge" pos="2.0 0.44985891050403426 5.220950617681526" axis="0 1 0" range="-10 10" limited="true" /></body><body name="leg_14"><geom pos="0.7007600978995012 -4 4.72654103483031" type="box" size="0.2 1 0.05" mass="1" /><joint name="leg_14_Hinge" pos="0.3503800489497506 -2.0 4.6765410348303105" axis="1 0 0" range="-10 10" limited="true" /></body><body name="leg_15"><geom pos="4 0.8997178210080685 5.2709506176815255" type="box" size="1 0.2 0.05" mass="1" /><joint name="leg_15_Hinge" pos="2.0 0.44985891050403426 5.220950617681526" axis="0 1 0" range="-10 10" limited="true" /></body><body name="leg_16"><geom pos="0.4955702548489218 6 4.567845554843578" type="box" size="0.2 1 0.05" mass="1" /><joint name="leg_16_Hinge" pos="0.2477851274244609 3.0 4.5178455548435785" axis="-1 0 0" range="-10 10" limited="true" /></body><body name="leg_17"><geom pos="0.4955702548489218 4 4.567845554843578" type="box" size="0.2 1 0.05" mass="1" /><joint name="leg_17_Hinge" pos="0.2477851274244609 2.0 4.5178455548435785" axis="-1 0 0" range="-10 10" limited="true" /></body></body></worldbody><actuator><motor name="leg_0_Hinge" gear="50" joint="leg_0_Hinge" /></actuator><actuator><motor name="leg_1_Hinge" gear="50" joint="leg_1_Hinge" /></actuator><actuator><motor name="leg_2_Hinge" gear="50" joint="leg_2_Hinge" /></actuator><actuator><motor name="leg_3_Hinge" gear="50" joint="leg_3_Hinge" /></actuator><actuator><motor name="leg_4_Hinge" gear="50" joint="leg_4_Hinge" /></actuator><actuator><motor name="leg_5_Hinge" gear="50" joint="leg_5_Hinge" /></actuator><actuator><motor name="leg_6_Hinge" gear="50" joint="leg_6_Hinge" /></actuator><actuator><motor name="leg_7_Hinge" gear="50" joint="leg_7_Hinge" /></actuator><actuator><motor name="leg_8_Hinge" gear="50" joint="leg_8_Hinge" /></actuator><actuator><motor name="leg_9_Hinge" gear="50" joint="leg_9_Hinge" /></actuator><actuator><motor name="leg_10_Hinge" gear="50" joint="leg_10_Hinge" /></actuator><actuator><motor name="leg_11_Hinge" gear="50" joint="leg_11_Hinge" /></actuator><actuator><motor name="leg_12_Hinge" gear="50" joint="leg_12_Hinge" /></actuator><actuator><motor name="leg_13_Hinge" gear="50" joint="leg_13_Hinge" /></actuator><actuator><motor name="leg_14_Hinge" gear="50" joint="leg_14_Hinge" /></actuator><actuator><motor name="leg_15_Hinge" gear="50" joint="leg_15_Hinge" /></actuator><actuator><motor name="leg_16_Hinge" gear="50" joint="leg_16_Hinge" /></actuator><actuator><motor name="leg_17_Hinge" gear="50" joint="leg_17_Hinge" /></actuator></mujoco>